<mujoco model="franka_panda_industrial_teleop">
    <compiler angle="radian" meshdir="franka_emika_panda/assets" autolimits="true"/>
    <option integrator="implicitfast" timestep="0.002"/>
    
    <default>
    <default class="panda">
      <material specular="0.5" shininess="0.25" />
      <joint armature="0.1" damping="1" axis="0 0 1" range="-2.8973 2.8973" />
      <general dyntype="none" biastype="affine" ctrlrange="-2.8973 2.8973" forcerange="-87 87" />
      <default class="finger">
        <joint axis="0 1 0" type="slide" range="0 0.04" limited="true" damping="0.05" armature="0.001" solimplimit="0.99 0.999 0.001" solreflimit="0.001 1" />
      </default>

      <default class="visual">
        <geom type="mesh" contype="0" conaffinity="0" group="2" />
      </default>
      <default class="collision">
        <geom type="mesh" group="3" />
        <default class="fingertip_pad_collision_1">
          <geom type="box" size="0.0085 0.004 0.0085" pos="0 0.0055 0.0445" />
        </default>
        <default class="fingertip_pad_collision_2">
          <geom type="box" size="0.003 0.002 0.003" pos="0.0055 0.002 0.05" />
        </default>
        <default class="fingertip_pad_collision_3">
          <geom type="box" size="0.003 0.002 0.003" pos="-0.0055 0.002 0.05" />
        </default>
        <default class="fingertip_pad_collision_4">
          <geom type="box" size="0.003 0.002 0.0035" pos="0.0055 0.002 0.0395" />
        </default>
        <default class="fingertip_pad_collision_5">
          <geom type="box" size="0.003 0.002 0.0035" pos="-0.0055 0.002 0.0395" />
        </default>
      </default>
    </default>
  </default>

  
    <asset>
    <material class="panda" name="white" rgba="1 1 1 1" />
    <material class="panda" name="off_white" rgba="0.901961 0.921569 0.929412 1" />
    <material class="panda" name="black" rgba="0.25 0.25 0.25 1" />
    <material class="panda" name="green" rgba="0 1 0 1" />
    <material class="panda" name="light_blue" rgba="0.039216 0.541176 0.780392 1" />

    
    <mesh name="link0_c" file="link0.stl" />
    <mesh name="link1_c" file="link1.stl" />
    <mesh name="link2_c" file="link2.stl" />
    <mesh name="link3_c" file="link3.stl" />
    <mesh name="link4_c" file="link4.stl" />
    <mesh name="link5_c0" file="link5_collision_0.obj" />
    <mesh name="link5_c1" file="link5_collision_1.obj" />
    <mesh name="link5_c2" file="link5_collision_2.obj" />
    <mesh name="link6_c" file="link6.stl" />
    <mesh name="link7_c" file="link7.stl" />
    <mesh name="hand_c" file="hand.stl" />

    
    <mesh file="link0_0.obj" />
    <mesh file="link0_1.obj" />
    <mesh file="link0_2.obj" />
    <mesh file="link0_3.obj" />
    <mesh file="link0_4.obj" />
    <mesh file="link0_5.obj" />
    <mesh file="link0_7.obj" />
    <mesh file="link0_8.obj" />
    <mesh file="link0_9.obj" />
    <mesh file="link0_10.obj" />
    <mesh file="link0_11.obj" />
    <mesh file="link1.obj" />
    <mesh file="link2.obj" />
    <mesh file="link3_0.obj" />
    <mesh file="link3_1.obj" />
    <mesh file="link3_2.obj" />
    <mesh file="link3_3.obj" />
    <mesh file="link4_0.obj" />
    <mesh file="link4_1.obj" />
    <mesh file="link4_2.obj" />
    <mesh file="link4_3.obj" />
    <mesh file="link5_0.obj" />
    <mesh file="link5_1.obj" />
    <mesh file="link5_2.obj" />
    <mesh file="link6_0.obj" />
    <mesh file="link6_1.obj" />
    <mesh file="link6_2.obj" />
    <mesh file="link6_3.obj" />
    <mesh file="link6_4.obj" />
    <mesh file="link6_5.obj" />
    <mesh file="link6_6.obj" />
    <mesh file="link6_7.obj" />
    <mesh file="link6_8.obj" />
    <mesh file="link6_9.obj" />
    <mesh file="link6_10.obj" />
    <mesh file="link6_11.obj" />
    <mesh file="link6_12.obj" />
    <mesh file="link6_13.obj" />
    <mesh file="link6_14.obj" />
    <mesh file="link6_15.obj" />
    <mesh file="link6_16.obj" />
    <mesh file="link7_0.obj" />
    <mesh file="link7_1.obj" />
    <mesh file="link7_2.obj" />
    <mesh file="link7_3.obj" />
    <mesh file="link7_4.obj" />
    <mesh file="link7_5.obj" />
    <mesh file="link7_6.obj" />
    <mesh file="link7_7.obj" />
    <mesh file="hand_0.obj" />
    <mesh file="hand_1.obj" />
    <mesh file="hand_2.obj" />
    <mesh file="hand_3.obj" />
    <mesh file="hand_4.obj" />
    <mesh file="finger_0.obj" />
    <mesh file="finger_1.obj" />
  </asset>

  
    
    <worldbody>
        <light pos="0 0 3" dir="0 0 -1" directional="true" castshadow="true"/>
        <geom name="floor" type="plane" size="2 2 0.1" rgba="0.15 0.15 0.15 1.0"/>

        <!-- Manipulation Workspace Table (Surface at Z = 0) -->
        <body name="table" pos="0.45 0.0 0.0">
            <geom name="table_top" type="box" size="0.25 0.50 0.01" pos="0 0 -0.01" rgba="0.25 0.25 0.25 1.0"/>
        </body>

        
        <!-- Manipulation Cube Object 0 -->
        <body name="cube_0" pos="0.397 -0.132 0.02">
            <joint name="cube_joint_0" type="free"/>
            <geom name="cube_geom_0" type="box" size="0.02 0.02 0.02" rgba="0.9 0.45 0.1 1.0" mass="0.05" condim="6" friction="1.0 0.005 0.0001"/>
        </body>
        <!-- Manipulation Cube Object 1 -->
        <body name="cube_1" pos="0.422 -0.308 0.02">
            <joint name="cube_joint_1" type="free"/>
            <geom name="cube_geom_1" type="box" size="0.02 0.02 0.02" rgba="0.1 0.6 0.9 1.0" mass="0.05" condim="6" friction="1.0 0.005 0.0001"/>
        </body>
        <!-- Manipulation Cube Object 2 -->
        <body name="cube_2" pos="0.388 0.211 0.02">
            <joint name="cube_joint_2" type="free"/>
            <geom name="cube_geom_2" type="box" size="0.02 0.02 0.02" rgba="0.8 0.1 0.8 1.0" mass="0.05" condim="6" friction="1.0 0.005 0.0001"/>
        </body>
        <!-- Manipulation Cube Object 3 -->
        <body name="cube_3" pos="0.489 0.219 0.02">
            <joint name="cube_joint_3" type="free"/>
            <geom name="cube_geom_3" type="box" size="0.02 0.02 0.02" rgba="0.9 0.9 0.1 1.0" mass="0.05" condim="6" friction="1.0 0.005 0.0001"/>
        </body>
        <!-- Manipulation Cube Object 4 -->
        <body name="cube_4" pos="0.496 -0.276 0.02">
            <joint name="cube_joint_4" type="free"/>
            <geom name="cube_geom_4" type="box" size="0.02 0.02 0.02" rgba="0.1 0.8 0.5 1.0" mass="0.05" condim="6" friction="1.0 0.005 0.0001"/>
        </body>

        <body name="link0_left" childclass="panda" pos="0 0.25 0.0"><inertial mass="0.629769" pos="-0.041018 -0.00014 0.049974" fullinertia="0.00315 0.00388 0.004285 8.2904e-7 0.00015 8.2299e-6" /><geom mesh="link0_0" material="off_white" class="visual" /><geom mesh="link0_1" material="black" class="visual" /><geom mesh="link0_2" material="off_white" class="visual" /><geom mesh="link0_3" material="black" class="visual" /><geom mesh="link0_4" material="off_white" class="visual" /><geom mesh="link0_5" material="black" class="visual" /><geom mesh="link0_7" material="white" class="visual" /><geom mesh="link0_8" material="white" class="visual" /><geom mesh="link0_9" material="black" class="visual" /><geom mesh="link0_10" material="off_white" class="visual" /><geom mesh="link0_11" material="white" class="visual" /><geom mesh="link0_c" class="collision" /><body name="link1_left" pos="0 0 0.333"><inertial mass="4.970684" pos="0.003875 0.002081 -0.04762" fullinertia="0.70337 0.70661 0.0091170 -0.00013900 0.0067720 0.019169" /><joint name="joint1_left" /><geom material="white" mesh="link1" class="visual" /><geom mesh="link1_c" class="collision" /><body name="link2_left" quat="1 -1 0 0"><inertial mass="0.646926" pos="-0.003141 -0.02872 0.003495" fullinertia="0.0079620 2.8110e-2 2.5995e-2 -3.925e-3 1.0254e-2 7.04e-4" /><joint name="joint2_left" range="-1.7628 1.7628" /><geom material="white" mesh="link2" class="visual" /><geom mesh="link2_c" class="collision" /><body name="link3_left" pos="0 -0.316 0" quat="1 1 0 0"><joint name="joint3_left" /><inertial mass="3.228604" pos="2.7518e-2 3.9252e-2 -6.6502e-2" fullinertia="3.7242e-2 3.6155e-2 1.083e-2 -4.761e-3 -1.1396e-2 -1.2805e-2" /><geom mesh="link3_0" material="white" class="visual" /><geom mesh="link3_1" material="white" class="visual" /><geom mesh="link3_2" material="white" class="visual" /><geom mesh="link3_3" material="black" class="visual" /><geom mesh="link3_c" class="collision" /><body name="link4_left" pos="0.0825 0 0" quat="1 1 0 0"><inertial mass="3.587895" pos="-5.317e-2 1.04419e-1 2.7454e-2" fullinertia="2.5853e-2 1.9552e-2 2.8323e-2 7.796e-3 -1.332e-3 8.641e-3" /><joint name="joint4_left" range="-3.0718 -0.0698" /><geom mesh="link4_0" material="white" class="visual" /><geom mesh="link4_1" material="white" class="visual" /><geom mesh="link4_2" material="black" class="visual" /><geom mesh="link4_3" material="white" class="visual" /><geom mesh="link4_c" class="collision" /><body name="link5_left" pos="-0.0825 0.384 0" quat="1 -1 0 0"><inertial mass="1.225946" pos="-1.1953e-2 4.1065e-2 -3.8437e-2" fullinertia="3.5549e-2 2.9474e-2 8.627e-3 -2.117e-3 -4.037e-3 2.29e-4" /><joint name="joint5_left" /><geom mesh="link5_0" material="black" class="visual" /><geom mesh="link5_1" material="white" class="visual" /><geom mesh="link5_2" material="white" class="visual" /><geom mesh="link5_c0" class="collision" /><geom mesh="link5_c1" class="collision" /><geom mesh="link5_c2" class="collision" /><body name="link6_left" quat="1 1 0 0"><inertial mass="1.666555" pos="6.0149e-2 -1.4117e-2 -1.0517e-2" fullinertia="1.964e-3 4.354e-3 5.433e-3 1.09e-4 -1.158e-3 3.41e-4" /><joint name="joint6_left" range="-0.0175 3.7525" /><geom mesh="link6_0" material="off_white" class="visual" /><geom mesh="link6_1" material="white" class="visual" /><geom mesh="link6_2" material="black" class="visual" /><geom mesh="link6_3" material="white" class="visual" /><geom mesh="link6_4" material="white" class="visual" /><geom mesh="link6_5" material="white" class="visual" /><geom mesh="link6_6" material="white" class="visual" /><geom mesh="link6_7" material="light_blue" class="visual" /><geom mesh="link6_8" material="light_blue" class="visual" /><geom mesh="link6_9" material="black" class="visual" /><geom mesh="link6_10" material="black" class="visual" /><geom mesh="link6_11" material="white" class="visual" /><geom mesh="link6_12" material="green" class="visual" /><geom mesh="link6_13" material="white" class="visual" /><geom mesh="link6_14" material="black" class="visual" /><geom mesh="link6_15" material="black" class="visual" /><geom mesh="link6_16" material="white" class="visual" /><geom mesh="link6_c" class="collision" /><body name="link7_left" pos="0.088 0 0" quat="1 1 0 0"><inertial mass="7.35522e-01" pos="1.0517e-2 -4.252e-3 6.1597e-2" fullinertia="1.2516e-2 1.0027e-2 4.815e-3 -4.28e-4 -1.196e-3 -7.41e-4" /><joint name="joint7_left" /><geom mesh="link7_0" material="white" class="visual" /><geom mesh="link7_1" material="black" class="visual" /><geom mesh="link7_2" material="black" class="visual" /><geom mesh="link7_3" material="black" class="visual" /><geom mesh="link7_4" material="black" class="visual" /><geom mesh="link7_5" material="black" class="visual" /><geom mesh="link7_6" material="black" class="visual" /><geom mesh="link7_7" material="white" class="visual" /><geom mesh="link7_c" class="collision" /><body name="hand_left" pos="0 0 0.107" quat="0.9238795 0 0 -0.3826834"><inertial mass="0.73" pos="-0.01 0 0.03" diaginertia="0.001 0.0025 0.0017" /><geom mesh="hand_0" material="off_white" class="visual" /><geom mesh="hand_1" material="black" class="visual" /><geom mesh="hand_2" material="black" class="visual" /><geom mesh="hand_3" material="white" class="visual" /><geom mesh="hand_4" material="off_white" class="visual" /><geom mesh="hand_c" class="collision" /><body name="left_finger_left" pos="0 0 0.0584"><inertial mass="0.015" pos="0 0 0" diaginertia="2.375e-6 2.375e-6 7.5e-7" /><joint name="finger_joint1_left" class="finger" /><geom mesh="finger_0" material="off_white" class="visual" /><geom mesh="finger_1" material="black" class="visual" /><geom mesh="finger_0" class="collision" /><geom class="fingertip_pad_collision_1" /><geom class="fingertip_pad_collision_2" /><geom class="fingertip_pad_collision_3" /><geom class="fingertip_pad_collision_4" /><geom class="fingertip_pad_collision_5" /></body><body name="right_finger_left" pos="0 0 0.0584" quat="0 0 0 1"><inertial mass="0.015" pos="0 0 0" diaginertia="2.375e-6 2.375e-6 7.5e-7" /><joint name="finger_joint2_left" class="finger" /><geom mesh="finger_0" material="off_white" class="visual" /><geom mesh="finger_1" material="black" class="visual" /><geom mesh="finger_0" class="collision" /><geom class="fingertip_pad_collision_1" /><geom class="fingertip_pad_collision_2" /><geom class="fingertip_pad_collision_3" /><geom class="fingertip_pad_collision_4" /><geom class="fingertip_pad_collision_5" /></body></body></body></body></body></body></body></body></body></body>
        <body name="link0_right" childclass="panda" pos="0 -0.25 0.0"><inertial mass="0.629769" pos="-0.041018 -0.00014 0.049974" fullinertia="0.00315 0.00388 0.004285 8.2904e-7 0.00015 8.2299e-6" /><geom mesh="link0_0" material="off_white" class="visual" /><geom mesh="link0_1" material="black" class="visual" /><geom mesh="link0_2" material="off_white" class="visual" /><geom mesh="link0_3" material="black" class="visual" /><geom mesh="link0_4" material="off_white" class="visual" /><geom mesh="link0_5" material="black" class="visual" /><geom mesh="link0_7" material="white" class="visual" /><geom mesh="link0_8" material="white" class="visual" /><geom mesh="link0_9" material="black" class="visual" /><geom mesh="link0_10" material="off_white" class="visual" /><geom mesh="link0_11" material="white" class="visual" /><geom mesh="link0_c" class="collision" /><body name="link1_right" pos="0 0 0.333"><inertial mass="4.970684" pos="0.003875 0.002081 -0.04762" fullinertia="0.70337 0.70661 0.0091170 -0.00013900 0.0067720 0.019169" /><joint name="joint1_right" /><geom material="white" mesh="link1" class="visual" /><geom mesh="link1_c" class="collision" /><body name="link2_right" quat="1 -1 0 0"><inertial mass="0.646926" pos="-0.003141 -0.02872 0.003495" fullinertia="0.0079620 2.8110e-2 2.5995e-2 -3.925e-3 1.0254e-2 7.04e-4" /><joint name="joint2_right" range="-1.7628 1.7628" /><geom material="white" mesh="link2" class="visual" /><geom mesh="link2_c" class="collision" /><body name="link3_right" pos="0 -0.316 0" quat="1 1 0 0"><joint name="joint3_right" /><inertial mass="3.228604" pos="2.7518e-2 3.9252e-2 -6.6502e-2" fullinertia="3.7242e-2 3.6155e-2 1.083e-2 -4.761e-3 -1.1396e-2 -1.2805e-2" /><geom mesh="link3_0" material="white" class="visual" /><geom mesh="link3_1" material="white" class="visual" /><geom mesh="link3_2" material="white" class="visual" /><geom mesh="link3_3" material="black" class="visual" /><geom mesh="link3_c" class="collision" /><body name="link4_right" pos="0.0825 0 0" quat="1 1 0 0"><inertial mass="3.587895" pos="-5.317e-2 1.04419e-1 2.7454e-2" fullinertia="2.5853e-2 1.9552e-2 2.8323e-2 7.796e-3 -1.332e-3 8.641e-3" /><joint name="joint4_right" range="-3.0718 -0.0698" /><geom mesh="link4_0" material="white" class="visual" /><geom mesh="link4_1" material="white" class="visual" /><geom mesh="link4_2" material="black" class="visual" /><geom mesh="link4_3" material="white" class="visual" /><geom mesh="link4_c" class="collision" /><body name="link5_right" pos="-0.0825 0.384 0" quat="1 -1 0 0"><inertial mass="1.225946" pos="-1.1953e-2 4.1065e-2 -3.8437e-2" fullinertia="3.5549e-2 2.9474e-2 8.627e-3 -2.117e-3 -4.037e-3 2.29e-4" /><joint name="joint5_right" /><geom mesh="link5_0" material="black" class="visual" /><geom mesh="link5_1" material="white" class="visual" /><geom mesh="link5_2" material="white" class="visual" /><geom mesh="link5_c0" class="collision" /><geom mesh="link5_c1" class="collision" /><geom mesh="link5_c2" class="collision" /><body name="link6_right" quat="1 1 0 0"><inertial mass="1.666555" pos="6.0149e-2 -1.4117e-2 -1.0517e-2" fullinertia="1.964e-3 4.354e-3 5.433e-3 1.09e-4 -1.158e-3 3.41e-4" /><joint name="joint6_right" range="-0.0175 3.7525" /><geom mesh="link6_0" material="off_white" class="visual" /><geom mesh="link6_1" material="white" class="visual" /><geom mesh="link6_2" material="black" class="visual" /><geom mesh="link6_3" material="white" class="visual" /><geom mesh="link6_4" material="white" class="visual" /><geom mesh="link6_5" material="white" class="visual" /><geom mesh="link6_6" material="white" class="visual" /><geom mesh="link6_7" material="light_blue" class="visual" /><geom mesh="link6_8" material="light_blue" class="visual" /><geom mesh="link6_9" material="black" class="visual" /><geom mesh="link6_10" material="black" class="visual" /><geom mesh="link6_11" material="white" class="visual" /><geom mesh="link6_12" material="green" class="visual" /><geom mesh="link6_13" material="white" class="visual" /><geom mesh="link6_14" material="black" class="visual" /><geom mesh="link6_15" material="black" class="visual" /><geom mesh="link6_16" material="white" class="visual" /><geom mesh="link6_c" class="collision" /><body name="link7_right" pos="0.088 0 0" quat="1 1 0 0"><inertial mass="7.35522e-01" pos="1.0517e-2 -4.252e-3 6.1597e-2" fullinertia="1.2516e-2 1.0027e-2 4.815e-3 -4.28e-4 -1.196e-3 -7.41e-4" /><joint name="joint7_right" /><geom mesh="link7_0" material="white" class="visual" /><geom mesh="link7_1" material="black" class="visual" /><geom mesh="link7_2" material="black" class="visual" /><geom mesh="link7_3" material="black" class="visual" /><geom mesh="link7_4" material="black" class="visual" /><geom mesh="link7_5" material="black" class="visual" /><geom mesh="link7_6" material="black" class="visual" /><geom mesh="link7_7" material="white" class="visual" /><geom mesh="link7_c" class="collision" /><body name="hand_right" pos="0 0 0.107" quat="0.9238795 0 0 -0.3826834"><inertial mass="0.73" pos="-0.01 0 0.03" diaginertia="0.001 0.0025 0.0017" /><geom mesh="hand_0" material="off_white" class="visual" /><geom mesh="hand_1" material="black" class="visual" /><geom mesh="hand_2" material="black" class="visual" /><geom mesh="hand_3" material="white" class="visual" /><geom mesh="hand_4" material="off_white" class="visual" /><geom mesh="hand_c" class="collision" /><body name="left_finger_right" pos="0 0 0.0584"><inertial mass="0.015" pos="0 0 0" diaginertia="2.375e-6 2.375e-6 7.5e-7" /><joint name="finger_joint1_right" class="finger" /><geom mesh="finger_0" material="off_white" class="visual" /><geom mesh="finger_1" material="black" class="visual" /><geom mesh="finger_0" class="collision" /><geom class="fingertip_pad_collision_1" /><geom class="fingertip_pad_collision_2" /><geom class="fingertip_pad_collision_3" /><geom class="fingertip_pad_collision_4" /><geom class="fingertip_pad_collision_5" /></body><body name="right_finger_right" pos="0 0 0.0584" quat="0 0 0 1"><inertial mass="0.015" pos="0 0 0" diaginertia="2.375e-6 2.375e-6 7.5e-7" /><joint name="finger_joint2_right" class="finger" /><geom mesh="finger_0" material="off_white" class="visual" /><geom mesh="finger_1" material="black" class="visual" /><geom mesh="finger_0" class="collision" /><geom class="fingertip_pad_collision_1" /><geom class="fingertip_pad_collision_2" /><geom class="fingertip_pad_collision_3" /><geom class="fingertip_pad_collision_4" /><geom class="fingertip_pad_collision_5" /></body></body></body></body></body></body></body></body></body></body>

        <!-- Left Mocap Target -->
        <body name="mocap_target_left" mocap="true" pos="0.554 0.25 0.625">
            <geom name="mocap_geom_left" type="sphere" size="0.02" rgba="0 1 0 0.4" contype="0" conaffinity="0"/>
            <geom type="cylinder" size="0.002" fromto="0 0 0 0.06 0 0" rgba="1 0 0 0.8" contype="0" conaffinity="0"/>
            <geom type="cylinder" size="0.002" fromto="0 0 0 0 0.06 0" rgba="0 1 0 0.8" contype="0" conaffinity="0"/>
            <geom type="cylinder" size="0.002" fromto="0 0 0 0 0 0.06" rgba="0 0 1 0.8" contype="0" conaffinity="0"/>
        </body>

        <!-- Right Mocap Target -->
        <body name="mocap_target_right" mocap="true" pos="0.554 -0.25 0.625">
            <geom name="mocap_geom_right" type="sphere" size="0.02" rgba="0 1 0 0.4" contype="0" conaffinity="0"/>
            <geom type="cylinder" size="0.002" fromto="0 0 0 0.06 0 0" rgba="1 0 0 0.8" contype="0" conaffinity="0"/>
            <geom type="cylinder" size="0.002" fromto="0 0 0 0 0.06 0" rgba="0 1 0 0.8" contype="0" conaffinity="0"/>
            <geom type="cylinder" size="0.002" fromto="0 0 0 0 0 0.06" rgba="0 0 1 0.8" contype="0" conaffinity="0"/>
        </body>
    </worldbody>

    <!-- Weld constraints to drag hands with mocaps -->
    <equality>
        <weld name="teleop_weld_left" body1="hand_left" body2="mocap_target_left" relpose="0 0 0 1 0 0 0" solimp="0.9 0.95 0.001" solref="0.02 1"/>
        <weld name="teleop_weld_right" body1="hand_right" body2="mocap_target_right" relpose="0 0 0 1 0 0 0" solimp="0.9 0.95 0.001" solref="0.02 1"/>
    </equality>

    <!-- Gripper position controllers mapping straight to sliding joints -->
    <actuator>
        <position name="finger_actuator1_left" joint="finger_joint1_left" ctrlrange="0 0.04" kp="100"/>
        <position name="finger_actuator2_left" joint="finger_joint2_left" ctrlrange="0 0.04" kp="100"/>
        <position name="finger_actuator1_right" joint="finger_joint1_right" ctrlrange="0 0.04" kp="100"/>
        <position name="finger_actuator2_right" joint="finger_joint2_right" ctrlrange="0 0.04" kp="100"/>
    </actuator>
</mujoco>